#Promise, async, await

#Promise
- a JavaScript object for asynchronous operation
###State
- pending (while operation) — > fulfilled or rejected
###Producer vs Consumer
####Producer
- when new Promise is created, the executor runs automatically!
####Consumers: then, catch, finally
```js
// Producer
const promise = new Promise((resolve, reject) => {
  // doing some heavy work (network, read files)
  console.log('doing sth...');
  setTimeout(() => {
    resolve('paige'); // 잘 성공했으면 resolve라는 콜백에다가 전달 
    reject(new Error('no network')) // Error-javascript object
  }, 2000);
});

// executor: (resolve, reject) 
// resolve : 기능을 정상적으로 수행해서 마지막에 data를 전달할 callback 함수 
// reject: 기능을 수행하다가 중간에 문제가 생기면 호출할 callback 함수 

// Consumers
// promise가 정상적으로 실행되어서 마지막으로 resolve에 전달 된 값이 then의 parameter로 들어가게 됨 
promise
  .then(value => {
    console.log(value); //'paige'가 들어오게 됨
  })
  .catch(error => {
    console.log(error);
  })
// catch가 없으면 Uncaught syntax error 라고 뜸
// 만약 실패를 하면 catch로 처리 
// then을 호출하면, promise를 리턴하기 때문에, 그 리턴 된 promise의 catch를 호출할 수 있음   
  .finally(() => {
    console.log('finally')
  });
// 성공과 실패 없이 항상 호출 됨 
```
###Promise Chaining
- promise chain는 같은 객체를 리턴하지 않고 항상 다른 promise를 리턴하게 됨
```js
const fetchNumber = new Promise((resolve, reject) => {
  setTimeout(() => resolve(1), 1000) // +1sec
});

//then은 값을 바로 전달해도 되고 또는 promise 전달 가능

fetchNumber 
  .then(num => num * 2) // 2
  .then(num => num * 3) // 6
  .then(num => {
    return new Promise((resolve, rejcet) => {
      setTimeout(() => resolve(num - 1), 1000); // 5
    });
  })
  .then(num => console.log(num)); // 2초 뒤 5가 뜸, +1 sec
  // then에서 받아오는 값이 하나이고 바로 전달하는 거면 생략 가능
  //(console.log)
```
###Error Handling
- then(onFulfilled, onRejected) 두개의 parameters를 넘길 수 있음
- onFulfilled = then에서 성공했을 때 실행하는 함수
- onRejected = then에서 예외처리해 줄 수 있는 함수

```js
function wait(sec){
  return new Promise((resolve, reject) => {
    setTimeout(() => {
      reject('error!');
    }, sec * 1000);
  });
}

---
// try {
//   wait(3);
// }catch(e) {
//   console.error(e)
// }
// 이렇게 처리해주면 uncaught(in promise)이 잡히지 않음 예외를 발생하는 타이밍이
// try가 싸고 있는 코드가 실행되는 타이밍이 아니라, 나중에 콜스택으로 콜스택이 비어있을 때, 
// 나중에 타이머가 큐에 넣고 그 큐의 내용이 콜스택이 쌓였기 때문에, promise의 catch를 이용해야 됨

---
wait(3)
  .catch(e => {
    console.log('1st catch', e)
    // throw e 를 하게 되면 뒤에 catch의 console이 찍힘
  }) // 첫번쨰 catch는 promise의 executer의 실행 상태를 나타내주는 애 
  .catch(e => {
    console.log('1st catch', e)
  }) // 윗 catch 자체의 행동이 실행 됐는지에 해당하는 promise에 걸어둔 catch 
// 그렇기 떄문에 두번째 catch의 console은 찍히지 않는다

---
wait(3)
  .then(
    () => {
      console.log('done!!!');
    },
    e => {
      console.log('1st catch in Then', e);
    }
  )
  .catch(e => {
    console.log('2nd catch', e);
  });
// 1st catch in Then error! 
// 두번째 catch는 실행되지 않음 

---
wait(3)
  .then(
    () => {
      console.log('done!!!'); // 성공했을 때 onfulfilled
    },
    e => {
      console.log('1st catch in Then', e); // onrejected 
      throw new Error('throw in Then')
    }
  )
  .catch(e => {
    console.log('2nd catch', e);
  });
// 1st catch in Then error! 
// 2nd catch Error: throw in Then
```

```js
const getHen = () =>
  new Promise((resolve, reject) => {
    setTimeout(() => resolve('🐓'), 1000);
  })
  
const getEgg = hen => 
  new Promise((resolve, reject) => {
    setTimeout(() => resolve(`${hen} => 🥚`), 1000);
  })
  
const cook = egg =>
  new Promise((resolve, reject) => {
    setTimeout(() => resolve(`${egg} => 🍳`), 1000);
  })
  

getHen() 
  .then(hen => getEgg(hen)) //(getEgg)
  .then(egg => cook(egg)) //(cook)
  .then(meal => console.log(meal)); //(console.log) 3초 뒤에 🐓 => 🥚 => 🍳 
// 콜백함수를 전달할 때, 받아오는 value를 바로 다른 함수에서 전달할 때 생략 가능

---
const getHen = () =>
    new Promise((resolve, reject) => {
      setTimeout(() => resolve('🐓'), 1000);
    })

const getEgg = hen =>
    new Promise((resolve, reject) => {
      setTimeout(() => reject(new Error(`error! ${hen} => 🥚`), 1000))
    })

const cook = egg =>
    new Promise((resolve, reject) => {
      setTimeout(() => resolve(`${egg} => 🍳`), 1000)
    })

getHen() 
  .then(getEgg) 
  .then(cook) 
  .then(console.log)
  .catch(console.log); 
  // 만약에 없으며 Uncaught(in promise)Error: error! 🐓 => 🥚 라고 뜨지만
  // catch 를 사용하면 Error: error! 🐓 => 🥚 
  
---
getHen() 
  .then(getEgg) // 바로 catch로 실패를 했을 때 처리를 해주면 끝까지 계속 진행이 됨 
  .catch(error => {
    return '🥯'
  })
  .then(cook)
  .then(console.log) 
  .catch(console.log); //🥯 => 🍳
```

```js
const sleep = (wait) => {
  return new Promise((resolve) => {
    setTimeout(() => {
      resolve('hello')
    }, wait);
  });
}

function runPromise() {
  resetTitle();
  playVideo();

  sleep(1000).then((param) => {
    console.log(param);
    pauseVideo();
    displayTitle();
    return 'world'
  })
      .then((param) => {
        console.log(param);
        sleep(500);
      })
      .then(highlightTitle)
      .then(sleep.bind(null, 2000)) 
      .then(resetTitle)
      .then(resetTitle)
      .catch(err => {
        console.log(err);
      })
}
// resolve()를 다른 함수의 콜백으로 넘겨줘야 하는데(setTimeout 등) 
// 이때 데이터도 함께 넘겨줘야 한다면, 익명 함수로 감싸주거나 bind()를 사용
```

###async & await
- clear style of using promise
-promise를 위에 더 간편한 API를 제공하는 것 => Syntactic Sugar
####async
- 키워드를 쓰면 바로 함수앞에 쓰면 코드 블럭이 promise가 되어버림
- async 함수의 리턴은 promise의 resolve와 동일하다고 할 수 있음
```js
function fetchUser() {
  return new Promise((resolve, reject) => {
    resolve('paige') // Resolve나 reject가 없으면 상태는 항상 Promise {<pending>}
  })
}

const user = fetchUser();
user.then(console.log) // paige
console.log(user); // Promise {<fulfilled>: "paige"}

async function fetchUser() {
    return 'paige'
}

const user = fetchUser();
user.then(console.log) // paige
console.log(user); // Promise {<fulfilled>: "paige"}
```

```js
function gotoCodestates() {
  return new Promise((resolve, reject) => {
    setTimeout(() => { resolve('1. go to codestates') },
        Math.floor(Math.random() * 100) + 1)
  })
}

function sitAndCode() {
    return new Promise((resolve, reject) => {
        setTimeout(() => { resolve('2. sit and code') }, 
        Math.floor(Math.random() * 100) + 1)
    })
}
 
function eatLunch() {
    return new Promise((resolve, reject) => {
        setTimeout(() => { resolve('3. eat lunch') }, 
        Math.floor(Math.random() * 100) + 1)
    })
}
 
function goToBed() {
    return new Promise((resolve, reject) => {
        setTimeout(() => { resolve('4. goToBed') }, Math.floor(Math.random() * 100) + 1)
    })
}
 
const result = async () => {
    const one = await gotoCodestates();
    console.log(one)
 
    const two = await sitAndCode();
    console.log(two)
 
    const three = await eatLunch();
    console.log(three)
 
    const four = await goToBed();
    console.log(four)
}
 
result();
```
####await
- async 함수 안에서만 사용 가능
- promise를 기달릴 수 있는 아이(fulfilled나 rejected 될 때까지 기다려줌)

```js
function delay(ms){
  return new Promise(resolve => setTimeout(resolve, ms));
}

async function getApple(){
  await delay(3000);
  return '🍎'; // 3초 있다가 🍎 리턴
}

async function getBanana(){
  await delay(3000);
  return '🍌'; // 3초 있다가 🍌 리턴
}

function pickFruits(){
  return getApple().then(apple => {
    return getBanana().then(banana => `${apple} + ${banana}`);
  });
}

pickFruits().then(console.log)// 6초 후에 🍎 + 🍌 => callback hell
---
async function pickFruits(){
  const apple = await getApple() // 3초 후에 🍎
  const banana = await getBanana() // 3초 후에 🍌
  return `${apple} + ${banana}`;
}
pickFruits().then(console.log) // 6초 후에 🍎 + 🍌 

---
async function getApple(){
  await delay(3000);
  throw 'error'
  return '🍎'; 
}

async function pickFruits(){
  try { // Try 안에는 예외가 발생할 수 있는 코드
    const apple = await getApple() // 3초 후에 🍎
    const banana = await getBanana() // 3초 후에 🍌
  } catch(e){ // try 에서 발생하는 예외에는 catch로 넘어와서 처리 
    console.log(e)
  }
  return `${apple} + ${banana}`;
}
// 에러 처리

---
// 이렇게 쓸 수도 있지만 하지 않고 밑에 있는 API 방법 사용함
async function pickFruits(){
  const applePromise = getApple()  // promise를 만들면 바로 promise안에 있는 코드블럭 실행
  const bananaPromise = getBanana()
  const apple = await getApple()
  const banana = await getBanana()
  return `${apple} + ${banana}`;  // 병렬적으로 동시에 실행 3초 후에 🍎 + 🍌
}

---
// promise API 사용
function pickAllFruits(){
  return Promise.all([getApple(), getBanana()])
  // promise 배열을 전달하게되면 모든 promise가 병렬적으로 다 받을때까지 모아줌 
  .then(fruits => fruits.join(' + '))
}
pickAllFruits().then(console.log) // 3초 후에 🍎 + 🍌

---
async function getBanana(){
  await delay(1000);
  return '🍌';
}

function pickOnlyOne(){
  return Promise.race([getApple(), getBanana()])
  // 배열에 전달된 promise 중에서 가장 먼저 값을 리턴하는 아이만 전달
}
pickOnlyOne().then(console.log); 🍌
```
###Error Handling
```js
async function myAsyncFun(){
    throw 'myAsyncError!'
}
const result = myAsyncFun()// Uncaught (in promise) myAsyncError!
console.log(result) // Promise {<rejected>: "myAsyncError!"}

// promise생성하는 단계에서 reject로 예외 발생
// async 함수에서는 동기적으로 실행되는 함수에서 예외를 발생하는 방법과 동일하게 throw
// 그렇기 때문에 catch 로 잡아야 됨

const result = myAsyncFun().catch(e => {
  console.error(e);
}) // 'myAsyncError!'

---
function wait(sec){
  return new Promise((resolve) => {
    setTimeout(() => {
      // resolve('done');
      reject('wait Error')
    }, sec * 1000);
  });
}
asnyc function myAsyncFun() {
  console.log(new Date());
  await wait(3).catch(e ==> {
    console.error(e); // wait Error
  });
  // try{
  //   await wait(3)
  // } catch(e){
  //   console.error(e)
  // } 위랑 같음 
  console.log(result) // undefined가 됨 그 이유는 await이 기다리는 promise는 
  // wait(3)인 new promise를 통해서 리턴된 것이 아니라 catch를 통해서 리턴된 promise를 await
  // promise가 정상적으로 됐을 때, catch는 앞에서 넘겨준 resolve 값을 그대로 resolve
  // 예외를 발생해서 catch로 왔는데, catch는 어떤 값도 리턴하지 않았음 그래서 undefined
  console.log(new Date());
}
const result = myAsyncFun();

---
// 만약에 async과 await에서 우리가 의도하지 않게 발생시킨 문법이나 오타같은 경우
// uncaught refernce error가 생김 
// 이것을 처리하려면 
// myAsyncFun().catch((e) => console.log(e))// uncaught는 빼고 error 부분만 나옴
```
####reference:
- https://www.youtube.com/channel/UC_4u-bXaba7yrRz_6x6kb_w
- https://www.youtube.com/channel/UC9hWQRe4QrUivXN3VO2iuMA